Workbook

Sheet FMPP
A1: FY | B1: FAIN | C1: Organizaton | D1: Award Amount | E1: Published Project Description
A2: 2022 | B2: AM22FMPPTN1130 | C2: Jonesborough Locally Grown | D2: 150727.83 | E2: Jonesborough Locally Grown (JLG) is a 501(c)(3) non-profit that connects farmers, food, and the community to grow a vibrant local food system. JLG operates two markets: Boone Street Market (BSM), a year-round local foods store, and Jonesborough Farmers Market (JFM), a tailgate farmers market. Both are producer-only that source primarily within 100 miles of Jonesborough, TN. JLG keeps fees low to benefit the vendor and supports over 100 vendors, many of whom are small or beginning farmers. JLG markets operate with significant volunteer support, donations and fundraisers – somewhat unreliable labor and funding sources, as the COVID-19 pandemic demonstrated. For the long-term financial stability of BSM and JFM and viability of JLG vendors, sales must increase to avoid radically changing the low vendor fee structure JLG currently employs. JLG was awarded a FMPP grant in 2018, allowing the start of an intensive marketing campaign. The previous grant was successful despite challenges presented by the pandemic, but rising inflation and overhead costs have increased the sales threshold required to sustain JLG markets. This project builds on the sampling and advertising elements of the previous project – and adds an important consumer demand: online ordering. With FMPP funds to support these initiatives, sales at BSM and JFM are projected to increase 15% by the end of the project period. Increasing sales in addition to foot traffic and retaining vendors are key to the long-term financial stability of BSM and JFM – and, therefore, the sustainability of the farmers and vendors supported by JLG markets.
A3: 2022 | B3: AM22FMPPAZ1133 | C3: City of Winslow | D3: 198392.81 | E3: Through this project, the Mother Road Farmers Market in Winslow, Arizona, will: Develop, coordinate, and expand local direct producer-to-consumer markets; Increase access to locally grown agricultural products; and Support small farms, new and beginning farmers, and/or underserved producers. The project will establish a full-time Farmers Market Coordinator to support current vendors, add additional food vendors (targeting produce), create programs, promote the market to the community, and evaluate project activities. Expected outcomes are to increase the amount of locally grown produce and food products available to residents by adding 10 produce vendors and creating a consignment program; increase income for local growers – with a focus on small, new, and/or under resourced growers; and improve access to fresh, locally grown food for low-income residents, which includes the community’s Indigenous and Hispanic populations.
A4: 2022 | B4: AM22FMPPAZ1134 | C4: Nalwoodi Denzhone: Strength and Beauty Community, Inc. | D4: 231388 | E4: This project will address the economic hardships facing the San Carlos Apache communities by building the Tribe’s capacity of supporting local-food enterprises with direct producer-to-consumer marketing technical assistance. Project activities include creating a marketing plan, the development of regional networks supporting local-food aggregation and distribution, establishing operation policies, food safety plans, standard operating procedures required for a successful direct producer-to-consumer marketing. Project deliverables will be utilized in the provision of targeted technical assistance and training to beginning and socially disadvantaged farmers, ranchers, and food businesses as a form of job/career training for Apache people. Project outcomes include a strengthened regional food economy on the San Carlos Apache Reservation, increased access to and consumption of local food, and job creation spurred by related economic development.
A5: 2022 | B5: AM22FMPPCA1135 | C5: Project New Village | D5: 250000 | E5: The purpose of the People’s Produce Mobile Farmers Market is to bring healthy, fairly-priced, locally-grown produce and other nutritious foods to low-income residents and food assistance beneficiaries using a refrigerated food truck operated by Project New Village, a 501(3)(c) grassroots nonprofit. The project’s service area will encompass eight weekly sites throughout Greater Southeastern San Diego, including the City of San Diego’s Promise Zone, the City of Lemon Grove, and National City. The project will provide a food retail shopping experience to consumers, meeting them at natural points of service such as libraries, YMCAs, community clinics, church parking lots, and other community-oriented gathering spaces. This project will improve equitable access to good food, which Project New Village defines as food that is: sustainable, healthy, affordable, and accessible to all residents. The project will engage new small farmers and producers, conduct culturally-competent marketing activities to market healthy food products and promote food assistance programs, reaching more than 15,000 customers.
A6: 2022 | B6: AM22FMPPCA1138 | C6: Central Coast Ag Network dba City Farm SLO | D6: 249919.95 | E6: “Scaling and Expanding San Luis Obispo (SLO) County Farmer Collaborative Partnerships” will measurably address major local and regional barriers to central coast farmers as well as vulnerable/underserved/ socially disadvantaged (low income- low access) communities relating to equitable and inclusive market opportunities and consumer access. This project will build a Farmer Collaborative that offers sustained supportive services and trainings to empower, and benefit limited resource, beginning, socially disadvantaged, and veteran farmers. In addition, the project will collaborate with Harvestly to expand online sales and Slow Money SLO to integrate farmers with the SLO County Farm to School Program. This project provides capacity needed to unify small-scale, new/ beginning farmers and ranchers, as well as underserved/ socially disadvantaged and veteran producer/ consumer communities. Direct beneficiaries include current and future City Farm SLO tenants participating in the Farmer Collaborative, SLO County Farmers, consumers, school districts, and the regional economy. The project’s work plan acts as a strategic and structural backbone to growing partnerships in a way that enables farmers to share administrative, knowledge, equipment, and other resources. The project also provides farmers access to extensive trainings, toolkits, onboarding, marketing, and support services. It is intended that this project will act as a pilot demonstration that can be rapidly adopted, replicated, and scaled throughout the County.
A7: 2022 | B7: AM22FMPPCA1140 | C7: Jefferson Economic Development Institute | D7: 100000 | E7: The project seeks to strengthen the regional food system infrastructure in Siskiyou County, CA by expanding the Mount Shasta Farmer’s Market and providing development opportunities for the area’s beginning farmers. Through collaboration with other organizations and farmers’ markets, and by supporting the business development of small-scale farmers and producers, this project seeks to strengthen the role of regional farmers’ markets in the direct-to-consumer supply chain while also supporting the development of beginning farmers. Project goals include increasing the number of customers patronizing the Mount Shasta Farmers’ Market, actively integrating beginning farmers/producers into the market, facilitating the creation of new value-added products, providing workshops on subjects identified by project stakeholders, identifying opportunities for regional farmers’ markets to collaborate, and creating new organizations focused on outreach to new customers.
A8: 2022 | B8: AM22FMPPCA1141 | C8: Pajaro Valley Community Health Trust | D8: 198245.2 | E8: This project will sustain and build the capacity of El Mercado, a California-certified, seasonal, and health-centric farmer’s market located in an area with concentrated poverty, limited access to supermarkets or locally grown food, and high rates of health disparities. The project’s goals are to build the long-term organizational capacity of El Mercado by doubling the foot traffic, number of agricultural producers, and average gross sales over a three-year period. Project activities will focus on increasing foot traffic through consumer- centric marketing efforts and community engagement, and subsequently growing the number of participating California-certified agricultural producers. The project will enable the expansion of a direct producer-to-consumer market, increasing access to and availability of locally and regionally produced agricultural products.
A9: 2022 | B9: AM22FMPPCO1136 | C9: Initium Health | D9: 229120 | E9: The project will bring together a multidisciplinary team to Shepard a group of Colorado agricultural producer through a process to identify available consumer markets, assess each operation’s challenges and opportunities, and map a process to successfully reach the market(s) that best fits each operation. Project deliverables include a toolkit for producers to enhance their market strategy within modern marketing frameworks, and a facilitated information exchange between farmers and partners specializing in aggregating and advertising local farm produce. Project outcomes include enabling local farms to maximize their capacity, reach new markets, and expand their presence in incumbent markets.
A10: 2022 | B10: AM22FMPPDE1101 | C10: New Castle County | D10: 125109 | E10: The New Castle County (NCC) Department of Community Services (DCS) will develop, coordinate, and expand direct producer-to-consumer markets, increase producers' economic opportunity, and expand access and availability of locally and regionally produced agricultural products through the acquired Bellevue Farmers Market and its new Reader's Café Farm-to-Table, Farm Fresh Initiative. This project aligns with the NCC DCS' Live Healthy Initiative to provide access to fresh, healthy agricultural food to low-income and low-access (LI/LA) communities while providing a viable market for producers to earn an income. The NCC DCS will use the FMPP funding to develop new market opportunities for and expand direct producer-to-consumer sales opportunities at the Bellevue Farms Market and the Reader's Café Farm-to-Table, Farm Fresh Market. This project will also target outreach, marketing, and promotion to engage new and existing regional and local farmers and producers and promote agricultural products available at the Bellevue Farmers Market and the Reader's Café Farm-to-Table, Farm Fresh Market. The goal is to create new economic opportunities for regional and local farmers and producers by recruiting new and established repeat customers through partnerships and community engagement with USDA LI/LA Census Tracts, other low-income communities, and the general public. The NCC DCS is committed to increasing consumption and access to locally and regionally produced agricultural products, as demonstrated through years of experience engaging producers at its weekly farmers markets throughout New Castle County.
A11: 2022 | B11: AM22FMPPFL1117 | C11: Village of Wellington | D11: 68864 | E11: The Village of Wellington will use grant funding to improve the promotion and marketing of the Lakeside Market at Wellington Town Center Farmers Market. The goals for the Wellington Farmers Market Project are to increase the farmers market attendance, increase the number of vendors, improve the cultural diversity of those vendors, and engage the public through more active participation in healthy educational presentations.
A12: 2022 | B12: AM22FMPPFL1126 | C12: Clara White Mission | D12: 249813.18 | E12: The Clara White Mission (CWM) will use FMPP Capacity Building grant funds to support their efforts to expand a regional farmers market network and training program at the Mission’s agritourism destination in Northwest Jacksonville, White Harvest Farms (WHF). The White Harvest Regional Farmers Market will strengthen local food system infrastructure in a food desert community. This project will include up to 50 local farmers, ranchers, and regional food stakeholders to sell in-person at the farmers market, online and stock products in a retail space. This project builds a regional network of farmers for marketing goods direct-to-consumer and increases market opportunities for farmers, ranchers, and regional food stakeholders. The program will also expand CWM training in food safety.
A13: 2022 | B13: AM22FMPPGA1127 | C13: Retaaza | D13: 152093 | E13: Retaaza will build a new supply chain pathway (infrastructure) in rural Southeast Georgia. Our project establishes a Mobile Market to change the food landscape in Clinch and Ware counties, serving as a much-needed oasis in a food desert to overcome barriers to healthy eating and increase access to fresh foods in pockets of extreme poverty. Local farmers are also important piece of the solution, to achieve the mission of connecting hungry Georgians to available local foods. Families will have healthy options available to them without the limitation of lack of transportation and farmers will be able to increase their income by selling produce that previously went to waste
... A170: 2024 | B170: FMPP24001894 | C170: Cornell Cooperative Extension of Nassau County | D170: 99728.07 | E170: The goal of CCE Nassau’s Eat Local - Shop Local Promotion Program is to spread awareness of the benefits eating and shopping locally-grown and sourced foods has on individuals, local businesses, and communities, and will serve to support the promotion of the CCE Nassau Farmers Market, as well as other avenues for Long Islanders to access farm fresh and local food and goods.

Sheet LFPP
A1: FY | B1: FAIN | C1: Organizaton | D1: Award Amount | E1: Published Project Description
A2: 2022 | B2: AM22LFPPCA1115 | C2: AG Link, Incorporated | D2: 500000 | E2: Ag Link’s 2022 FMPP Marketplace grant project will meet the needs of local producers to sell their farm fresh products directly to consumers through a new roadside stand and innovative online solutions in collaboration with an established supply chain partner. The goals of this project are to increase the numbers of local producers engaged in direct to consumer marketing; connect consumers to local producers for products and farm information and provide an innovative marketing and distribution channel for farmers to engage their social networks to sell their products directly to consumers. The purpose of this grant project is to develop new market opportunities for local producers to sell directly to consumers through development of a new retail stand in addition to an online farmers market. The project will increase returns for farmers making their operations more sustainable by increasing consumption of and access to local products by consumers benefiting the local economy. This project will expand Ag Link’s local food business from wholesale distribution to schools to include direct support of local producers, selling new value-added products directly to consumers.
A3: 2022 | B3: AM22LFPPCA1094 | C3: North Coast Growers' Association | D3: 410722 | E3: North Coast Growers’ Association (NCGA) will work with local/regional food producers to implement a distribution hub that will make it possible for producers to market and distribute their food more efficiently and economically while retaining brand and location identity. “Harvest Hub” will increase market access for producers, supporting their economic vitality by linking them with institutional buyers and other wholesale markets, as well as assessing and addressing producer needs in terms of technology, marketing, and infrastructure for storage, packaging, and distribution to facilitate their participation in wholesale markets. NCGA will engage Humboldt County Office of Education (HCOE) to transition their local food purchasing to the Harvest Hub. New systems for ordering and distribution will be developed and piloted so that Harvest Hub will procure local food for Humboldt County school districts’ meal purchasing programs. NCGA will work with Cal Poly Humboldt (CPH), a CA State University campus, to identify barriers to their local food purchasing goals. Funds from this grant will be used to map needs and barriers of CPH, collaboratively create a plan to update policies and standard operating procedures to overcome these barriers and begin to source locally grown and raised food to help meet their local purchasing goals. The Harvest Hub will benefit local farmers and students. Farmers will be able to increase their markets without increasing costs or workload. Students will have more access to nutrient dense produce throughout the school year to connect them more deeply with their local food system.
A4: 2022 | B4: AM22LFPPCA1105 | C4: Fiery Ginger Farm, LLC | D4: 500000 | E4: Fiery Ginger Farm, LLC was established in West Sacramento, CA in 2015. From the beginning, our intent has been to grow the highest quality produce for school kitchens. Small farmers recognize firsthand the benefits of stable institutional markets. The grant will use the knowledge and relationships that have been built over the last seven years to continue to open the door for other small farmers to gain access to institutional markets. The grant will continue to develop market connections and forward contracts while also providing logistical support, technical assistance, and training for both farmers and food service personnel.
A5: 2022 | B5: AM22LFPPCA1138 | C5: Old Grove Orange, Inc | D5: 432873 | E5: Old Grove Orange’s Expanding Local Food Systems project aims to increase economic opportunity for local farmers, including new/beginning and BIPOC farmers, by connecting them to a growing network of institutional markets in the Inland Empire. As the farmer-pioneer of California’s Farm to School movement, Old Grove Orange (OGO), a farmer-led food hub, has over 16 years of experience connecting a roster of 40+ local farmers to a Farm to School market of 200,000+ students. However, despite a steady increase in demand for fresh, local produce in this region, small farmers continue to struggle to provide the quantities or variety needed by institutional buyers, develop the unique Covid-era food processing/packaging sought by institutional buyers, and obtain the food safety certifications recognized by institutional buyers.This project will allow OGO to upgrade its infrastructure and enhance the processing, aggregation, distribution, and the development of the value-added agricultural products requested for by itsinstitutional clients; to broaden OGO’s customer base by developing new institutional markets for local food products; and to recruit, support, and provide more local farmers with access to institutional buyers. By investing in these three areas, Old Grove will be able to support at least 10 new farmers, increase sales of local agricultural products by 35%, and develop 10 new markets in the form of K-12 public school districts, university cafeterias, and local restaurants.
A6: 2022 | B6: AM22LFPPKY1159 | C6: God's Pantry Food Bank, Inc. | D6: 465658.56 | E6: God’s Pantry Food Bank (GPFB) serves 50 counties in Central and Eastern Kentucky, supporting more than 450 member food pantries and meal programs. Their total food distribution of 41.8 million pounds in 2021 included 13 million pounds of fresh produce. With team partners Appalachian Regional Healthcare (ARH) and Kentucky Educational Development Corporation (KEDC), GPFB is coordinating efforts to increase farm to institution distribution in southeast Kentucky, anchored by the food warehouse GPFB is developing in Hazard. GPFB’s planned facility will serve as a satellite distribution facility to improve food supply to member pantries in the distressed seven-county area. This facility will also provide supply chain infrastructure supporting farm-to-institution initiatives currently underway at ARH and KEDC. Anchoring efforts to supply more fresh fruits, vegetables, and other foods from local and regional sources, this facility will improve nutrition for patients, students, employees, and the community at large. GPFB’s food warehouse, with dry and cold storage, will fill an important gap in the regional food system, currently served by facilities located up to 230 miles away.
A7: 2022 | B7: AM22LFPPMT1119 | C7: Livingston Food Resource Center | D7: 300000 | E7: Livingston Food Resource Center (LFRC) project will promote and support Park County, Montana’s local food system through expanding access to and availability of locally produced foods for regional residents. As a leader in the community, LFRC has the ability to promote and support the local food system by increasing aggregation, processing, and distribution of local produce through: 1. expanding LFRC’s aggregation of local and regional food products to support local food systems; 2. creating value-added agricultural products through the processing of local produce for distribution through the LFRC; 3. increasing the distribution of agricultural products and value-added agricultural products in the region through increasing the capacity of the LFRC’s current programs, including meal and product distribution programs serving pre-K-12 students, seniors, oncology patients, and low-income individuals and families; 4. utilizing LFRC’s Community Bakery and Community Kitchen to further connect and strengthen the relationships between local producers and local food entrepreneurs while supporting the development of strategies to increase the inclusion of local food products in institutional settings to create growth in the local retail food market and economy; 5. and supporting new and established farmers and ranchers to help them succeed and to keep produce local; During this grant period of 9/30/2022 to 9/29/2025, LFRC will source an additional $300,000 of produce and meat from local farms. This project will be sustained after the grant through expanding operations, increasing local food access and demand, and furthering sustainability of the local food system.
A8: 2022 | B8: AM22LFPPMT1179 | C8: Lake County Community Development Corporation | D8: 491701.55 | E8: Institutional markets are increasingly seeking out local and responsibly grown food to add to their food service menus. The Northwest Food Hub Network, a collaboration between three food hubs in Montana and Washington, was created to help respond to these institutional market demands by providing one ordering platform in which institutions can access large quantities of local and regional products. However, the food processing capacity within the Network is limited, and institutions are continuing to ask for value-added food products that are easily integrated into their food operations. This project builds on the success of the Northwest Food Hub Network by increasing the processing capacity for the NWFHN, identifying and creating value-added food products for the institutional marketplace, creating effective marketing materials for the developed products, and providing necessary technical assistance and trainings for local and regional food processors. Mission West will work collaboratively with partners including Kitchen Sync Strategies and Montana State University Food Lab to complete these project objectives. This project will lead to increased sales for the NWFHN, which will ultimately benefit the 211 small to mid-size family farms that are connected to the Network, and will develop best practices for processing and product development that will be shared with interested organizations nationwide.
A9: 2022 | B9: AM22LFPPNC1140 | C9: Working Landscapes | D9: 499951 | E9: This project represents an unprecedented collaboration among five mission-driven food processors, seven food hubs, and 75 farmers and fishermen. Together, these partners will supply 41 North Carolina institutions with a wider array of value-added, locally- sourced foods than they have previously been able to purchase. Each of the 24 products developed and marketed, including fresh-cut produce; pasture-raised chicken, pork, and beef; seafood; and heat-and-serve meals, will be designed for ease of use in institutional kitchens. A subaward will support the development and production of shelf-stable fruit jerky, a wholesome, locally-sourced alternative to the unhealthy snacks offered through after-school programs, summer meals, and other institutional programs.
A10: 2022 | B10: AM22LFPPNC1175 | C10: Farmer Foodshare--DONE | D10: 499949.2 | E10: Farmer Foodshare will grow, diversify and expand our Food Hub by executing a post-pandemic revitalization project aimed at the development, coordination, and expansion of local and regional food business enterprises to increase access to and availability of locally and regionally produced agricultural products in the rapidly growing and agriculturally productive “Research Triangle” region of North Carolina. This project is designed to support this important program through strategic regrowth designed to scale up to pre-pandemic levels, while also diversifying our farmer network and updating operations and sales strategies for a post-pandemic world. Project Activities include: a marketing and outreach campaign; optimizing internal operations; identifying and adopting new software; food safety technical assistance to producers; intentional relationship-building with our farmers; broad partnerships with area food system service providers and institutional buyers; and extensive data collection, evaluation and dissemination. Deliverables and Expected Outcomes: These include expanding the number of farmers to 75 (+88%) and increasing volume of Food Hub purchases to $1 M+ annually by Yr. 3 (+158%); increasing the number of Food Hub buyers to 75 (+88%) and the volume of sales to $1.5 M annually (+158%); building a greater capacity to sustainably support the availability of regionally produced agricultural products and the development, expansion, coordination, and expansion of local and regional food businesses; creation of a robust set of refreshed brand assets and marketing tools to recruit farmers, promote their products; and educate nearly 200K area residents with information about accessing and using locally grown food products; and increasing capacity of FFS to serve farmers and local food institutional buyers by developing and institutionalizing data collection tools and practices for measuring Food Hub success. Intended Beneficiaries: There will be 199,670 direct beneficiaries, plus tens of thousands of customers and clients of our institutional buyers who will benefit from the increase in fresh, local, nutrient dense proteins and produce sourced through increased buying relationships throughout this project. 75 farm businesses will benefit, to the tune of $2.7 M returned to them OMB Number: 4040-0019 Expiration Date: 02/28/2022 * Project Abstract (Continued from previous page) in sales. 75 institutional buyers will benefit through $3.9 M in local food procurement to serve their clients and customers. Additionally, these activities will set Farmer Foodshare up to be sustainable in the long run, continuing to support our stakeholders in the years to come. Sub Recipient Activities: This project does not have sub awards; however it does have contractual partners. They include Carolina Farm Stewardship Association: will provide technical assistance to up to 12 farmers in applying for and securing their GAP certifications, including: coaching and instruction to provide direct TA, helping identify sustainable growers who may be eligible/interested in receiving this TA, with the goal of joining the FFS Farmer Network and accessing new sales markets. Mesh, our marketing consultant, will develop a flexible marketing and outreach campaign toolkit with brand assets, messaging, digital collateral, and customizable templates for content. Farm Fare, our Food Hub Operations & Software Consultant, will review FFS’s operations, and provide Food Hub operations optimization consulting to improve the daily functionality of FFS’s systems; and provide technical assistance for software adoption and implementation. Food Insight Group (FIG), our evaluator, will provide farmer survey question development, process evaluation, Survey and/or in-depth interview development, piloting, and implementation; Impact measurement; Data analysis; and annual reports. Black Farmers Market, will help FFS identify and connect with farmers of color who may be interested in learning about opportunities to sell their products through FFS’s Food Hub.
A11: 2022 | B11: AM22LFPPNH1173 | C11: University System of New Hampshire DONE | D11: 351053 | E11: To increase farm sales to institutions, a variety of approaches will be taken that create opportunities and programs for farms, food hubs and institutions to more easily develop buying/selling relationships. The project leverages opportunities like the new NH Food Hub Network, the relatively new Seacoast School Buying Group and interest in value added product development by two NH businesses. The NH Food Hub Network coordinator, also a new position, will be assisting in coordinating farm to institution sales. This project will also build on the established NH Harvest of the Month program by increasing the variety of monthly offerings making it easier for more farms and institutions to adopt the program, developing appropriate educational and marketing materials for all types of institutions and making the program relevant to the refugee and immigrant populations who now call NH home. Expected outcomes will increase availability of local food products on institutional menus through expansion of HoM and school buying group bids, develop, market, and distribute locally produced value added products for the institutional market and increase demand for locally produced foods by institutions working towards state and regional targets for institutional purchasing and farm production.
A12: 2022 | B12: AM22LFPPVT1096 | C12: Food Connects, Inc | D12: 286280 | E12: The overall goal of the project is to innovate in the supply chain to increase institutional, local food purchasing in Food Connects’ tri-state central New England service area. In 2021, Food Connects recognized the need to focus on institutional sales channels for our small and medium-scale New England producers. Activities to be performed include. but are not limited to, creating and printing marketing materials customized and co-branded to our customers' specs, with the goal to more deeply support customers in their efforts to tell their local food sourcing story, developing a product catalog (print and digital) to improve conversion rate with prospective institutional customers, especially major institutions, distribution of Annual Harvest of the Month calendars, posters, and other educational materials, collaborating with regional partners to support states in developing and improving local purchasing incentive programs for K-12 schools, and executing comprehensive sales push across the current service area to onboard institutional accounts whose food safety requirements Food Connects will be prepared to meet as of Fall 2022. Food Connects will also onboard and serve new institutional customers on new, to-be-launched delivery routes to underserved areas across Southeastern VT, Central, and Eastern MA, with a focus on major accounts, sell products from newly-onboarded suppliers to current customers, scout and onboard new regional suppliers with product offerings that fill important gaps in institutions' local food sourcing programs, develop a forward contracting model for supply, to align the needs and constraints of prospective major institutional customers with regional supply, build and execute a formal, forward-contracted, full-school-year Harvest of the Month local foods sourcing program for schools and colleges, and work with current major suppliers to identify opportunities to further tailor product offerings to the institutional foodservice market. Outcomes for this project include but are not limited to increasing the total number of products that may have success in reaching school customers based on specifications for key staples by 25, developing a product list to share with 30 key school customers to gauge interest, collecting feedback and begin planning for purchase and delivery, and increasing regional food sales to institutions from ~$300,000 in 2021 to $1 million by 2025. Additional outcomes include ensuring stakeholders gain technical knowledge about accessing regional foods and increasing the number of market access points that establish and increase engagement with regional producers.
A13: 2022 | B13: AM22LFPPWV1147 | C13: Yuraction Faction LLC DBA WV Harvest | D13: 482215 | E13: West Virginia Harvest (WVH) is a social enterprise, specialty food brand focused on positively impacting the local food system through innovative local products and services. The WV Harvest Farm to Institution application will connect producers and growers with state institutions through collaborative partnerships that result in stronger local food system in WV. WV Harvest will engage with the current growers, producers, and processors in the state of WV to begin the strategic aggregation of locally grown/raised/produced food products under the WV Harvest Brand. This includes creating an institution focused coordinated food chain and mid-tier value chain, purchasing locally grown/raised/processed products, and aggregating/storing locally grown/produced products in a central location. In addition, WV Harvest will expand on current work by informing the nutritional directors in K-12 and purchasing managers at WV State Institutions about the large selection of fresh and value-added food products available for purchase. This includes developing strategies and action tools for key decision makers of state institutions to become more informed of locally available products through WV Harvest. WV Harvest will market the opportunities for job creation and community growth associated with purchasing locally raised/grow/produced food products to students and administrators to elevate the local food system in WV. This includes informational displays and marketing installations in schools and institutions of higher education.
... A171: 2024 | B171: LFPP24001871 | C171: Board of Regents, NSHE, obo University of Nevada, Reno | D171: 88482.34 | E171: The Desert Farming Initiative is applying on behalf of the Nevada Farm Network to fund a two-year turnkey recruitment and training project, Enhancing Nevada Food Chain Initiatives. DFI will coordinate enhancement actions with partner programs, and facilitate a Leadership Committee made up of local producers and food entrepreneurs to strengthen connections between farmers and the mid-tier value chain. This proposal will leverage and expand on at least four other programs, including the Nevada Small Business Development Centers Made in Nevada e-commerce platform, the Transition to Organic Partnership Program, the Nevada Farm Apprenticeship Program, and the Local Food Network's Nourish and Flourish Non-Profit Commissary Kitchen. The Nevada Farm Network is the first online community of practice for Nevada farmers to access educational resources and make market connections. This project will additionally provide for a pilot project of value-add and processing trainings held at the Local Food Network's kitchen in urban Reno and partner organizations in rural Fallon.

Sheet RFSP
A1: FY | B1: FAIN | C1: Organizaton | D1: Award Amount | E1: Published Project Description
A2: 2022 | B2: AM22RFSPVA1058 | C2: Health Care Without Harm | D2: 999524 | E2: For more than a decade, the Farm to Institution (F2I) movement in Oregon has made significant strides engaging and coordinating efforts of institutional purchasers, government agencies, nonprofit organizations, and supply chain producers and processors. While successes have helped create lasting change in many institutions, the impact of these resources and partnerships has largely been focused on the Portland Metro Region. While almost 100,000 meals per day are served in institutions in the Portland area, there are more than twice as many meals served in institutions throughout the State. The purpose of this project is to leverage existing proofs of concept in farm to institution (F2I) and take them to scale at a state level. F2I will be catalyzed in different regions and rural areas of Oregon by establishing the Oregon Farm to Institution Collaborative (OFIC). Project objectives include Reconfigure the structure of a community of practice focused on F2I Strengthen regional infrastructure to support F2I projects that improve market channels for producers Address gaps and barriers identified in F2I work that contribute to inequities in the food system Develop a shared vision, common language, and purchasing standards for OFIC Key activities to be performed Design a recruitment strategy grounded in equity and inclusion principles and structure for OFIC Convene quarterly OFIC meetings Organize affinity groups, based on institutional setting, regions, and or topics of interest Hire two value chain coordinators in Oregon Hold four regional trainings to food service institutions, value chain coordinators, and producers Complete a land suitability study to determine institutional land for use in F2I projects Disseminate lessons learned and share impactDeliverables and expected outcomes Increase in the number of local producers that are connected to institutional market opportunities. By the end of the project, 200 local producers will have gained knowledge about new market opportunities through education and training. Pilot a farm to hospital project connecting producers to suitable land for food production. By the end of the project, five new or underserved farmers will have institutional land access for farming, and will have support related to food safety certifications and or business plans to meet institutional needs. Institutions will gain clarity on values based procurement. By the end of the project, 400 institutional partners will be reached through activities and communications from OFIC. Intended beneficiaries This project will benefit Oregon producers and processors through improved value chain coordination and connections to new institutional markets, thus providing institutions with more options and streamlined processes to purchase local and meet values based purchasing goals. Additionally, the project will benefit communities served by institutions throughout Oregon, like students, patients, and state employees, who will have improved access to healthy, locally grown and produced food.Subrecipient activities Partner organizations will participate in OFIC and affinity group processes and activities. Advisors and consultants will provide specific expertise and support, such as communications strategy, value chain coordination, product development technical assistance, meeting and group facilitation, and topical trainings (ex food safety, business planning). Producers will participate in the land suitability study and pilot project, or in other projects and activities of the OFIC.
A3: 2022 | B3: AM22RFSPCA1047 | C3: Siskiyou County Economic Development Council | D3: 353442 | E3: The agricultural economic sector in Siskiyou County is facing dire crisis due to persistent drought, year over year wildfires, and environmental pressures faced by small farms. This, paired with major market shifts, is culminating in the urgent decision for small farms across Siskiyou to innovate or exit. Siskiyou Economic Development Council (SEDC) is pairing with key partners throughout Siskiyou and the greater region to launch an initiative to expand market opportunities for Siskiyou producers. These efforts will create opportunities for farms to diversify and create business resiliency in the face of catastrophe. Connecting Siskiyou s Small Farms and Institutions will establish a critical network of local farms and regional institutional food buyers throughout Siskiyou County and its bordering communities. Through one on one technical assistance, SEDC will work to develop business plans and strategies that will connect key stakeholders and identify gaps in necessary infrastructure to cultivate a thriving farm to institution economy. This project will provide technical assistance to producers to develop capacity, skill and scale to address the institutional markets and will cultivate a strong foundation for ongoing connections between buyers and small farms. This program will build upon the SEDC s work in the agriculture sector and community food system and will leverage existing relationships with agricultural producers, support organizations, and expert business consultants. This program will strengthen the institutional local food system, identify gaps in infrastructure and supply chain partners, and connect local small farms to viable new markets in an effort to create long term sustainability for one of Siskiyou s most important economic sectors.
A4: 2022 | B4: AM22RFSPIA1061 | C4: Practical Farmers of Iowa | D4: 861356 | E4: Farmers of Iowa, Kitchen Table Consultants, and Iowa Valley RCAND D to preserve and significantly scale the institutional markets food hubs have developed in Iowa. This project will expand food hub capacity to capture more institutional sales, onboard new farmers, and grow sales territory to equitably serve more of the state. Our work will also leverage upcoming, short term institutional purchasing incentives to convert new institutions to permanent local food customers, transforming the scale of farm to institution in Iowa. Because of FarmTable Procurement AND Delivery s centrality to Iowa s local food system, the food hub network, and to farmers across Iowa, the partnership shares a commitment to transitioning the FarmTable food hub to a non profit and ensuring its long term sustainability. As a support partner with a strong state wide farmer network, Practical Farmers of Iowa (PFI) will provide key outreach and education for farmers to learn about food hubs and become food hub vendors. PFI will also administer and evaluate this project. Iowa Valley RCAND D will facilitate continued spaces for food hubs to collaborate with each other, while key experts at Kitchen Table Consultants will optimize food hub KPIs and provide business management coaching. Food Hub partners will maximize their added capacity made possible by this project, along with technical assistance, to add more farmer vendors, institutional customers, and territory to their individual businesses and expand the footprint of farm to institution in Iowa.
A5: 2022 | B5: AM22RFSPKY1063 | C5: The Kentucky Horticulture Council Inc. | D5: 689908 | E5: Grow Up Expanding Kentucky s regional produce market opportunities is an integrated systems approach that will expand Kentucky s regional food system impact by focusing on production, processing, distribution, and consumption of produce crops. We will leverage a public private partner network to increase production and market literacy while reducing known production and market barriers to support farms, businesses, and entrepreneurs that grow, store, process, market, and distribute produce locally and regionally. With focus and intentionality, the multi disciplinary project team will collectively address needs of at least 2,500 producers, 10 distribution partners, 43 institutional buyers, and 75,000 consumers of food products, with resulting system benefits including increased opportunities across market channels, economic improvement, job creation, enhanced ecosystem services, and expanded access to healthy food.
A6: 2022 | B6: AM22RFSPMA1035 | C6: TSNE MissionWorks, fiscalsponsor of Farm to Institution New | D6: 968375 | E6: This project invests in strengthening regional, equitable farm to institution (FTI) relationships and value chains in three New England Communities, which in coordination will lead to greater regional and values based food procurement across New England while shifting institutional power dynamics around race. Springfield, MA New Haven, CT and Cumberland County, ME will form a Cohort, represented by three community based organizations Springfield Food Policy Council, Cumberland County Food Security Council, City of New Haven Food System Policy Division who are already driving food systems change at the local level. Each of the community organizations will receive subawards to carry out their local organizing, community engagement, and value chain coordination activities. The partnership will be supported by three state departments of agriculture, who will connect partners to additional collaborators and technical assistance. Farm to Institution New England, a regional network backbone organization, will provide project coordination, connect the cohort with regional partners, resources, and trainings, and share stories and strategies developed in each community with the broader network. We believe that strong, inter woven and community driven foundations of FTI work lead to sustainable regional impact for New England producers and residents who eat at institutions. Three objectives drive this project 1. Community level Plan and implement multi sector community driven farm to institution initiatives in three New England communities, ensuring authentic engagement with residents who are most affected by this work and prioritizing disinvested communities. 2. Cohort level Establish a cohort among three communities for peer to peer learning, capacity building, and cross cohort leveraging. 3. Regional level Reinforce and grow New England s farm to institution movement by creating a dynamic and multi directional exchange of promising practices, success stories, and relationship building opportunities between the community cohort and the broader New England network.
A7: 2022 | B7: AM22RFSPMI1039 | C7: Groundwork Center for Resilient Communities, Inc | D7: 891100 | E7: Resilient Relationships, Resilient Supply builds upon established partnerships to strengthen the food system in lower Michigans Western Lakeshore Region to increase sales and consumption of locally grown foods from small and mid sized producers to schools, early child care and education (ECE) centers and emergency food providers The project increases community nutrition security by increasing access to healthy, local food for low income children, families, and citizens. We will support 34 stakeholder partners in filling gaps they have identified in infrastructure and supply chains to help markets grow. We will leverage MIs innovative state program, 10 Cents a Meal for Michigans Kids AND Farms, currently funded at 4.5 million, increasing local food purchasing power for schools, ECE centers, and eligible organizations feeding children via USDA child nutrition programs. Partners will leverage proven regional farm to food pantry initiatives that have grown in response to COVID 19. Lead partnersGroundwork Center for Resilient Communities, the principal of a food processing association, a supply chain logistics expert, and a local foods marketing enterprise with vast farmer connectionswill convene 5 Peer Learning Networks (PLNs) and provide farm to institution support and technical assistance to create stronger collaborations among 5 key stakeholder groups producers, distributors, processors aggregators, schools Early Care and Education (ECE) centers, and emergency food providers (EFP). The PLNs will provide the chance to network, identify needs, find opportunities and solutions, and build relationships. PLN members will attend Learning Journeys to PLN member sites to share best practices. They will have scholarships available to 5 key MI based food systems conferences to build knowledge and gain professional development. Implementation leads in the West MI and NW MI regions will match schools and ECE centers and EFP s to small and mid size farms and related food infrastructure, assisting partners in leveraging existing funding like 10 Cents a Meal and expanding upon farm to pantry initiatives. Subawards will go to 5 partner Core Team Members involved with the project West MI Food Processing Association will serve as Aggregation and Processing PLN Lead, EFP Implementation Lead and School Implementation Lead in 5 county west MI region, and provide Aggregation and Processing technical assistance Alden Services will serve as Distribution PLN Lead and provide Distribution Logistics technical assistance Taste the Local Difference will serve as Producer PLN Lead and also provide marketing technical assistance. Others Northwest Education Services will serve as School Implementation Lead in 5 county Grand Traverse Region Kent Co Essential Needs Task Force will serve as EFP Implementation Lead and School Implementation Lead in Kent Co. The roles they play are crucial for the execution of project objectives. Each offers expertise in their respective domains and are geographically located in regions that expand the reach and benefit of the project. Through technical assistance and coordinated efforts such as writing grants and obtaining loans we aim to increase capacity, develop new market opportunities for producers to expand local and regional food business enterprises, and promote food safety practices to ensure a safe and productive local and regional food system. 501,620 expected beneficiaries of this project include students in schools and ECE centers participating in 10 Cents a Meal, families and low income individuals utilizing EFPs, small and mid size farmers, processors, aggregators, distributors and businesses along the value added supply chain across the 16 county project region. We expect that our efforts in bringing together and engaging stakeholders of the food supply chain with lead to increased resilience and efficacy of work within the regional food system of MI s Western Lakeshore region.
A8: 2022 | B8: AM22RFSPOH1055 | C8: Cuyahoga County Board of Health | D8: 700000 | E8: Feed Our Future Planning, Partnerships and Projects to Increase Local Food Spending leverages local and regional partnerships to advance the collaborations necessary to build a regionally innovative and responsive farm to school (F2S) initiative that serves school aged children across Northern Ohio. The Cuyahoga County Board of Health (CCBH) serves as the backbone organization for Feed Our Future (FOF) Local Foods for Growing Minds, convening individuals and stakeholders throughout Ohio to advance the policy, environmental and systems changes needed to drive systemic change and build a more resilient food system. The project goals are to strengthen the mid tier value chain and increase local and regional food procurement by K 12 school districts. The key objectives of this partnership are to 1) strengthen the mid tier value chain to effectively serve K 12 school systems by increasing the number of producers in the supply chain 2) increase local food purchasing by K 12 school systems through the execution of a farm to school bid 3) increase the knowledge and skills of school meal program staff to menu, serve, and teach about local foods through the creation of two new curriculums and 4) expand organizational capacity to support regional local food system efforts, planning, partnership, and advocacy by hiring an equity consultant, facilitating ongoing meetings of the Feed Our Future Leadership Council, and engaging in new and enhancing existing partnerships to generate a regional farm to school strategic plan. The intended beneficiaries of this proposal include 1) local food system partners in Ohio, including 2 food hubs, 14 existing farm to school producers and local food business, and 5 10 new local food producers and businesses 2) K 12 school systems across a 38 county region in Northern Ohio 3) students attending urban, suburban, and rural school districts across a 38 county region in Northern Ohio and 4) engage 9 existing Feed Our Future Leadership Council member organizations and up to 40 new partners organizations. The activities outlined in this funding proposal require strong collaboration amongst a diverse set of partners. As such, the CCBH will subaward with the following partners to achieve project deliverables Verge Impact Partners (VIP). To provide technical assistance and build the capacity of FOF to design and carryout the work in ways that advance equitable outcomes for children, growers, and producers, on the bases of race, geography, and income. VIP currently serves as the equity consultant to Ohios Farm to Early Care and Education network. Pisanick Partners, LLC (PPLC). To create the Local Foods 101 and Local Menu Takeover 2.0 curriculums. PPLC has provided school nutrition consulting services to FOF since 2015.Local Food Connection (LFC). To co convene the Local Food System Taskforce. LFC will provide strategic direction and logistics coordination for the value chain. Oberlin Food Hub (OFH). To co convene the Local Food System Taskforce. OFH will serve as the value chain coordinator for K 12 schools. Muse Content Group (MCG). To provide the marketing and communication tools necessary to build and strengthen the regional food economy. MCG has served as the paid media partner for FOF since 2015. Ohio Schools Council (OSC). To co convene the School Foodservice Taskforce and work in partnership with CCBH to innovate a F2S procurement bid. OSC has partnered with CCBH on a F2S bid since 2015.
A9: 2022 | B9: AM22RFSPAZ1050 | C9: Pinnacle Prevention | D9: 475471.79 | E9: The purpose of the Implementing a Vibrant, Sustainable, and Equitable Community Food System Across the Arizona Food Systems Network (AZFSN) RFSP implementation and expansion project is to advance the implementation of the AZFSN Statewide Food Action Plan priorities, goals, objectives, and strategies for action. The intended project goals are to 1) strengthen capacity to support plan implementation, and 2) deepen connections across existing partners to institutionalize strategies for each plan priority area. Deliverables include 1) Convening the advisory team of the network to guide the implementation process ensuring representation across the diverse geography and communities of Arizona 2) Engaging network partners in participating and guiding the implementation of the action plan through virtual and in person convenings 3) Building capacity of partners to engage historically underserved communities and regional food producers otherwise isolated from the larger food system efforts in planning implementation efforts 4) Deepening relationships and participation in the partnership with rural and Indigenous food producers and communities with limited local food access by working with community champions that are trusted members of underserved communities 5) Hosting listening sessions with community voices from historically underserved communities and with local food producers, distributors and retailers to identify gaps and co design their local food system response to inform institutional response to meet these needs 6) Evaluation, sharing, and disseminating process outcomes across the implementation process to co design the next multi year food action plan 7) Working iteratively with local coalitions and partners to evaluate the effectiveness of the implementation and expansion work 8) Establishing shared measures and a platform to monitor progress and transparency in the implementation of activities and work 9) Sharing project results and best practices across state agencies, philanthropic partners, local coalitions and local governments, and private sector decision makers to institutionalize the adoption of processes and practices and, 10) Identifying, sharing, and securing critical resources to sustain the work. The benefits of this project are improved statewide collaboration and improved urban rural Indigenous trust and interdependence resulting in a stronger regional food system across Arizona. The outcomes of this project will result in reimagined local food economic opportunities leading to the long term vision of a more vibrant, sustainable, and equitable community food system for all Arizonans. Intended beneficiaries include socially disadvantaged farmers and ranchers, local food producers, individuals experiencing nutrition insecurity, and institutions implementing food system programs and services. This grant will include subcontracts for food action plan implementation support with eight (8) Arizona based regional food coalitions including Flagstaff Foodlink, Verde Valley Food Policy Council, Yuma HEAL Coalition, Pima County Food Alliance, Ajo Center for Sustainable Agriculture, Maricopa County Food System Coalition, Coalition for Farmland Preservation and a Tribal Collaborative workgroup.
